tests/test5.txt
A,1,B,75,900.0
A,2,S,735,1076.0
A,3,B,485,1000.0
A,4,S,421,1163.0
A,5,B,128,1041.0
A,6,S,614,1195.0
A,7,B,706,954.0
A,8,S,730,1060.0
A,9,B,388,991.0
A,10,S,480,1168.0
A,11,B,919,913.0
A,12,S,371,1063.0
A,13,B,401,1029.0
A,14,S,701,1141.0
A,15,B,365,963.0
A,16,S,75,1142.0
A,17,B,553,991.0
A,18,S,821,1072.0
A,19,B,290,958.0
A,20,S,475,1165.0
A,21,B,866,930.0
A,22,S,880,1148.0
A,23,B,382,982.0
A,24,S,973,1147.0
A,25,B,817,914.0
A,26,S,640,1186.0
A,27,B,828,1047.0
A,28,S,13,1167.0
A,29,B,299,982.0
A,30,S,840,1141.0
A,31,B,140,1008.0
A,32,S,499,1125.0
A,33,B,61,1020.0
A,34,S,898,1057.0
A,35,B,548,1004.0
A,36,S,448,1166.0
A,37,B,319,970.0
A,38,S,44,1150.0
A,39,B,558,968.0
A,40,S,920,1187.0
A,41,B,820,1006.0
A,42,S,642,1160.0
A,43,B,863,971.0
A,44,S,318,1145.0
A,45,B,236,990.0
A,46,S,820,1186.0
A,47,B,928,988.0
A,48,S,37,1086.0
A,49,B,719,919.0
A,50,S,119,1099.0
A,51,B,254,1029.0
A,52,S,589,1131.0
A,53,B,781,998.0
A,54,S,366,1076.0
A,55,B,815,1027.0
A,56,S,368,1138.0
A,57,B,285,906.0
A,58,S,623,1164.0
A,59,B,591,1047.0
A,60,S,631,1159.0
A,61,B,654,910.0
A,62,S,806,1179.0
A,63,B,61,923.0
A,64,S,754,1168.0
A,65,B,908,1025.0
A,66,S,747,1147.0
A,67,B,343,1028.0
A,68,S,417,1150.0
A,69,B,593,951.0
A,70,S,941,1170.0
A,71,B,852,955.0
A,72,S,177,1158.0
A,73,B,486,957.0
A,74,S,760,1133.0
A,75,B,670,1018.0
A,76,S,340,1123.0
A,77,B,371,940.0
A,78,S,104,1079.0
A,79,B,425,1040.0
A,80,S,435,1130.0
A,81,B,386,1042.0
A,82,S,548,1133.0
A,83,B,211,1019.0
A,84,S,36,1060.0
A,85,B,27,910.0
A,86,S,847,1123.0
A,87,B,263,1029.0
A,88,S,280,1152.0
A,89,B,291,945.0
A,90,S,2,1159.0
A,91,B,909,913.0
A,92,S,171,1190.0
A,93,B,870,994.0
A,94,S,661,1166.0
A,95,B,307,1034.0
A,96,S,536,1117.0
A,97,B,762,996.0
A,98,S,416,1102.0
A,99,B,397,989.0
A,100,S,631,1072.0
A,101,B,615,963.0
A,102,S,868,1169.0
A,103,B,72,1044.0
A,104,S,398,1120.0
A,105,B,336,993.0
A,106,S,2,1064.0
A,107,B,940,1008.0
A,108,S,554,1147.0
A,109,B,149,1042.0
A,110,S,35,1148.0
A,111,B,510,1046.0
A,112,S,18,1185.0
A,113,B,751,935.0
A,114,S,452,1200.0
A,115,B,22,906.0
A,116,S,529,1184.0
A,117,B,551,1025.0
A,118,S,243,1187.0
A,119,B,335,1024.0
A,120,S,89,1084.0
A,121,B,133,1033.0
A,122,S,441,1173.0
A,123,B,953,926.0
A,124,S,162,1099.0
A,125,B,277,900.0
A,126,S,746,1130.0
A,127,B,254,910.0
A,128,S,90,1056.0
A,129,B,885,1032.0
A,130,S,316,1151.0
A,131,B,158,975.0
A,132,S,125,1127.0
A,133,B,445,960.0
A,134,S,345,1071.0
A,135,B,889,956.0
A,136,S,183,1168.0
A,137,B,881,1012.0
A,138,S,914,1067.0
A,139,B,727,1012.0
A,140,S,595,1102.0
A,141,B,356,1025.0
A,142,S,266,1179.0
A,143,B,511,1002.0
A,144,S,583,1188.0
A,145,B,7,936.0
A,146,S,325,1147.0
A,147,B,427,911.0
A,148,S,723,1071.0
A,149,B,840,932.0
A,150,S,209,1055.0
A,151,B,999,942.0
A,152,S,511,1082.0
A,153,B,278,936.0
A,154,S,163,1184.0
A,155,B,154,954.0
A,156,S,217,1110.0
A,157,B,248,904.0
A,158,S,772,1140.0
A,159,B,362,983.0
A,160,S,901,1135.0
A,161,B,296,1040.0
A,162,S,101,1184.0
A,163,B,826,947.0
A,164,S,194,1063.0
A,165,B,324,1007.0
A,166,S,480,1156.0
A,167,B,171,986.0
A,168,S,880,1096.0
A,169,B,358,1040.0
A,170,S,622,1081.0
A,171,B,847,1036.0
A,172,S,963,1196.0
A,173,B,924,965.0
A,174,S,556,1123.0
A,175,B,343,988.0
A,176,S,516,1193.0
A,177,B,496,919.0
A,178,S,318,1113.0
A,179,B,900,968.0
A,180,S,516,1166.0
A,181,B,770,959.0
A,182,S,729,1193.0
A,183,B,1000,999.0
A,184,S,830,1180.0
A,185,B,451,905.0
A,186,S,987,1108.0
A,187,B,984,960.0
A,188,S,379,1173.0
A,189,B,813,917.0
A,190,S,300,1083.0
A,191,B,46,980.0
A,192,S,788,1097.0
A,193,B,791,911.0
A,194,S,552,1091.0
A,195,B,413,946.0
A,196,S,939,1131.0
A,197,B,351,914.0
A,198,S,501,1160.0
A,199,B,49,1032.0
A,200,S,724,1074.0
T,756,1047
M,27,B,72,1047.0
T,209,1055
T,90,1056
T,297,1057
X,150,S,209,1055.0
X,128,S,90,1056.0
M,34,S,601,1057.0
T,72,1047
T,416,1047
X,27,B,72,1047.0
M,59,B,175,1047.0
T,304,1057
M,34,S,297,1057.0
T,175,1047
T,510,1046
T,13,1044
X,59,B,175,1047.0
X,111,B,510,1046.0
M,103,B,59,1044.0
T,59,1044
T,163,1042
X,103,B,59,1044.0
M,81,B,223,1042.0
T,297,1057
T,683,1060
X,34,S,297,1057.0
M,8,S,47,1060.0
T,223,1042
T,101,1042
X,81,B,223,1042.0
M,109,B,48,1042.0
T,48,1042
T,128,1041
T,425,1040
T,296,1040
T,38,1040
X,109,B,48,1042.0
X,5,B,128,1041.0
X,79,B,425,1040.0
X,161,B,296,1040.0
M,169,B,320,1040.0
T,47,1060
T,36,1060
T,371,1063
T,194,1063
T,2,1064
T,228,1067
X,8,S,47,1060.0
X,84,S,36,1060.0
X,12,S,371,1063.0
X,164,S,194,1063.0
X,106,S,2,1064.0
M,138,S,686,1067.0
T,320,1040
T,604,1036
X,169,B,320,1040.0
M,171,B,243,1036.0
T,243,1036
T,124,1034
X,171,B,243,1036.0
M,95,B,183,1034.0
T,584,1067
M,138,S,102,1067.0
T,183,1034
T,133,1033
T,495,1032
X,95,B,183,1034.0
X,121,B,133,1033.0
M,129,B,390,1032.0
T,102,1067
T,345,1071
T,449,1071
X,138,S,102,1067.0
X,134,S,345,1071.0
M,148,S,274,1071.0
T,390,1032
T,49,1032
T,375,1029
X,129,B,390,1032.0
X,199,B,49,1032.0
M,13,B,26,1029.0
T,274,1071
T,117,1072
X,148,S,274,1071.0
M,18,S,704,1072.0
T,26,1029
T,254,1029
T,263,1029
T,237,1028
X,13,B,26,1029.0
X,51,B,254,1029.0
X,87,B,263,1029.0
M,67,B,106,1028.0
T,106,1028
T,815,1027
T,26,1025
X,67,B,106,1028.0
X,55,B,815,1027.0
M,65,B,882,1025.0
A,220,S,89,1042.0
T,882,1025
T,64,1025
X,65,B,882,1025.0
M,117,B,487,1025.0
T,89,1042
T,167,1072
X,220,S,89,1042.0
M,18,S,537,1072.0
T,487,1025
T,356,1025
T,6,1024
X,117,B,487,1025.0
X,141,B,356,1025.0
M,119,B,329,1024.0
T,329,1024
T,61,1020
T,211,1019
T,316,1018
X,119,B,329,1024.0
X,33,B,61,1020.0
X,83,B,211,1019.0
M,75,B,354,1018.0
T,354,1018
T,624,1012
X,75,B,354,1018.0
M,137,B,257,1012.0
T,26,1012
M,137,B,231,1012.0
T,537,1072
T,174,1072
X,18,S,537,1072.0
M,100,S,457,1072.0
T,457,1072
T,301,1074
X,100,S,457,1072.0
M,200,S,423,1074.0
T,231,1012
T,727,1012
T,42,1008
X,137,B,231,1012.0
X,139,B,727,1012.0
M,31,B,98,1008.0
T,98,1008
T,66,1008
X,31,B,98,1008.0
M,107,B,874,1008.0
T,423,1074
T,105,1076
X,200,S,423,1074.0
M,2,S,630,1076.0
A,232,S,227,1037.0
T,17,1008
M,107,B,857,1008.0
T,227,1037
T,168,1076
X,232,S,227,1037.0
M,2,S,462,1076.0
T,459,1008
M,107,B,398,1008.0
A,236,S,143,1029.0
A,237,S,959,1012.0
A,238,S,471,1050.0
A,239,S,917,1010.0
T,508,1010
M,239,S,409,1010.0
T,409,1010
T,418,1012
X,239,S,409,1010.0
M,237,S,541,1012.0
T,268,1012
M,237,S,273,1012.0
T,280,1008
M,107,B,118,1008.0
T,273,1012
T,143,1029
T,159,1050
X,237,S,273,1012.0
X,236,S,143,1029.0
M,238,S,312,1050.0
T,118,1008
T,324,1007
T,355,1006
X,107,B,118,1008.0
X,165,B,324,1007.0
M,41,B,465,1006.0
T,211,1050
M,238,S,101,1050.0
T,99,1050
M,238,S,2,1050.0
T,465,1006
T,142,1004
X,41,B,465,1006.0
M,35,B,406,1004.0
T,288,1004
M,35,B,118,1004.0
T,2,1050
T,373,1076
X,238,S,2,1050.0
M,2,S,89,1076.0
T,89,1076
T,366,1076
T,104,1079
T,109,1081
X,2,S,89,1076.0
X,54,S,366,1076.0
X,78,S,104,1079.0
M,170,S,513,1081.0
T,513,1081
T,438,1082
X,170,S,513,1081.0
M,152,S,73,1082.0
T,118,1004
T,376,1002
X,35,B,118,1004.0
M,143,B,135,1002.0
T,73,1082
T,300,1083
T,89,1084
T,37,1086
T,318,1091
X,152,S,73,1082.0
X,190,S,300,1083.0
X,120,S,89,1084.0
X,48,S,37,1086.0
M,194,S,234,1091.0
A,255,B,334,1055.0
T,216,1055
M,255,B,118,1055.0
T,118,1055
X,255,B,118,1055.0
A,257,S,492,1027.0
T,492,1027
T,188,1091
X,257,S,492,1027.0
M,194,S,46,1091.0
T,46,1091
T,537,1096
X,194,S,46,1091.0
M,168,S,343,1096.0
T,343,1096
T,556,1097
X,168,S,343,1096.0
M,192,S,232,1097.0
T,232,1097
T,119,1099
T,69,1099
X,192,S,232,1097.0
X,50,S,119,1099.0
M,124,S,93,1099.0
T,135,1002
T,379,1000
X,143,B,135,1002.0
M,3,B,106,1000.0
T,93,1099
T,416,1102
T,236,1102
X,124,S,93,1099.0
X,98,S,416,1102.0
M,140,S,359,1102.0
T,106,1000
T,188,999
X,3,B,106,1000.0
M,183,B,812,999.0
T,469,999
M,183,B,343,999.0
T,39,1102
M,140,S,320,1102.0
T,343,999
T,593,998
X,183,B,343,999.0
M,53,B,188,998.0
T,320,1102
T,409,1108
X,140,S,320,1102.0
M,186,S,578,1108.0
T,188,998
T,59,996
X,53,B,188,998.0
M,97,B,703,996.0
T,452,1108
M,186,S,126,1108.0
A,271,B,863,1083.0
T,126,1108
T,177,1110
X,186,S,126,1108.0
M,156,S,40,1110.0
T,113,1083
M,271,B,750,1083.0
T,40,1110
T,318,1113
T,536,1117
T,33,1120
X,156,S,40,1110.0
X,178,S,318,1113.0
X,96,S,536,1117.0
M,104,S,365,1120.0
A,275,B,158,1117.0
T,158,1117
T,669,1083
X,275,B,158,1117.0
